<mujoco model="panda scene">
  <include file="panda_nohand.xml"/>

  <statistic center="0.3 0 0.4" extent="2"/>

  <visual>
    <headlight diffuse="0.6 0.6 0.6" ambient="0.3 0.3 0.3" specular="0 0 0"/>
    <rgba haze="0.15 0.25 0.35 1"/>
    <global azimuth="90" elevation="-40"/>
  </visual>

  <asset>
    <texture type="skybox" builtin="gradient" rgb1="0.3 0.5 0.7" rgb2="0 0 0" width="512" height="3072"/>
    <texture type="2d" name="groundplane" builtin="checker" mark="edge" rgb1="0.2 0.3 0.4" rgb2="0.1 0.2 0.3"
      markrgb="0.8 0.8 0.8" width="300" height="300"/>
    <material name="groundplane" texture="groundplane" texuniform="true" texrepeat="5 5" reflectance="0.2"/>
  </asset>

  <worldbody>
    <light pos="0 0 1.5" dir="0 0 -1" directional="true"/>
    
    <geom name="floor" pos="0 0.5 -0.325" size="1 1 0.1" type="plane" contype="1" conaffinity="1"/>
    
    <body name="object" pos="0.65 -0.15 -0.275" >
      <geom rgba="1 1 1 0" type="sphere" size="0.05 0.05 0.05" density="1000" conaffinity="0"/>
      <geom rgba="1 1 1 1" type="box" size="0.05 0.05 0.05" density="1000" contype="1" conaffinity="0"/>
      <joint name="obj_slidey" type="slide" pos="0 0 0" axis="0 1 0" range="-10.3213 10.3" damping="0.5"/>
      <joint name="obj_slidex" type="slide" pos="0 0 0" axis="1 0 0" range="-10.3213 10.3" damping="0.5"/>
    </body>
    <body name="goal" pos="0.65 -0.15 -0.3240">
      <geom rgba="1 0 0 1" type="box" size="0.08 0.08 0.001" density='0.00001' contype="0" conaffinity="0"/>
      <joint name="goal_slidey" type="slide" pos="0 0 0" axis="0 1 0" range="-10.3213 10.3" damping="0.5"/>
      <joint name="goal_slidex" type="slide" pos="0 0 0" axis="1 0 0" range="-10.3213 10.3" damping="0.5"/>
    </body>
  </worldbody>

  <keyframe>
    <key name="key" qpos="0 0 0 -1.57079 0 1.57079 -0.7853 0 0 0 0"/>
  </keyframe>
</mujoco>
